Workbook
Name IQ_CH: 110000
Name IQ_CQ: 5000
Name IQ_CY: 10000
Name IQ_DAILY: 500000
Name IQ_FH: 100000
Name IQ_FQ: 500
Name IQ_FY: 1000
Name IQ_LTM: 2000
Name IQ_MONTH: 15000
Name IQ_NTM: 6000
Name IQ_WEEK: 50000
Name IQ_YTD: 3000
Name SplitsByYear: DividendHelper!$K$1:$M$12

Sheet Balance Sheet - Standardized
A1: Ticker | C1: LNN | D1: US | M1: Errors on check lines | N1: {=SUM(--ISERROR($C$13:$L$13),--ISERROR($C$17:$L$17),--ISERROR($C$25:$L$25),--ISERROR($C$34:$L$34),--ISERROR($C$36:$L$36),--ISERROR($C$42:$L$42),--ISERROR($C$46:$L$46),--ISERROR($C$58:$L$58),--ISERROR($C$60:$L$60),--ISERROR($C$62:$L$62),--ISERROR($C$69:$L$69),--ISERROR($C$76:$L$76),--ISERROR($C$83:$L$83),--ISERROR($C$85:$L$85),--ISERROR($C$91:$L$91),--ISERROR($C$103:$L$103),--ISERROR($C$105:$L$105),--ISERROR($C$107:$L$107),--ISERROR($C$112:$L$112),--ISERROR($C$119:$L$119),--ISERROR($C$121:$L$121),--ISERROR($C$122:$L$122), COUNT($C$13:$L$13) - COUNTIFS($C$13:$L$13,">-.1",$C$13:$L$13,"<.1"),COUNT($C$17:$L$17) - COUNTIFS($C$17:$L$17,">-.1",$C$17:$L$17,"<.1"),COUNT($C$25:$L$25) - COUNTIFS($C$25:$L$25,">-.1",$C$25:$L$25,"<.1"),COUNT($C$34:$L$34) - COUNTIFS($C$34:$L$34,">-.1",$C$34:$L$34,"<.1"),COUNT($C$36:$L$36) - COUNTIFS($C$36:$L$36,">-.1",$C$36:$L$36,"<.1"),COUNT($C$42:$L$42) - COUNTIFS($C$42:$L$42,">-.1", $C$42:$L$42,"<.1"),COUNT($C$46:$L$46) - COUNTIFS($C$46:$L$46,">-.1", $C$46:$L$46,"<.1"),COUNT($C$58:$L$58) - COUNTIFS($C$58:$L$58,">-.1", $C$58:$L$58,"<.1"),COUNT($C$60:$L$60) - COUNTIFS($C$60:$L$60,">-.1", $C$60:$L$60,"<.1"),COUNT($C$62:$L$62) - COUNTIFS($C$62:$L$62,">-.1", $C$62:$L$62,"<.1"),COUNT($C$69:$L$69) - COUNTIFS($C$69:$L$69,">-.1", $C$69:$L$69,"<.1"),COUNT($C$76:$L$76) - COUNTIFS($C$76:$L$76,">-.1", $C$76:$L$76,"<.1"),COUNT($C$83:$L$83) - COUNTIFS($C$83:$L$83,">-.1", $C$83:$L$83,"<.1"),COUNT($C$85:$L$85) - COUNTIFS($C$85:$L$85,">-.1", $C$85:$L$85,"<.1"),COUNT($C$91:$L$91) - COUNTIFS($C$91:$L$91,">-.1", $C$91:$L$91,"<.1"),COUNT($C$103:$L$103) - COUNTIFS($C$103:$L$103,">-.1", $C$103:$L$103,"<.1"),COUNT($C$105:$L$105) - COUNTIFS($C$105:$L$105,">-.1", $C$105:$L$105,"<.1"),COUNT($C$107:$L$107) - COUNTIFS($C$107:$L$107,">-.1", $C$107:$L$107,"<.1"),COUNT($C$112:$L$112) - COUNTIFS($C$112:$L$112,">-.1", $C$112:$L$112,"<.1"),COUNT($C$119:$L$119) - COUNTIFS($C$119:$L$119,">-.1", $C$119:$L$119,"<.1"),COUNT($C$121:$L$121) - COUNTIFS($C$121:$L$121,">-.1", $C$121:$L$121,"<.1"),COUNT($C$122:$L$122) - COUNTIFS($C$122:$L$122,">-.1", $C$122:$L$122,"<.1"))} -> 0
A2: Start Year | C2: ="FY "&RIGHT(C3,4)-9 -> FY 2016
A3: End Year | C3: ="FY "&IF(O5="Q4",LEFT(N5,4),LEFT(N5,4)-1) -> FY 2025
C4: 42613 | D4: 42978 | E4: 43343 | F4: 43708 | G4: 44074 | H4: 44439 | I4: 44804 | J4: 45169 | K4: 45535 | L4: 45900 | N4: EQY_RECENT_BS_QT | O4: EQY_RECENT_QT_END_QT
C5: 2016 A | D5: 2017 A | E5: 2018 A | F5: 2019 A | G5: 2020 A | H5: 2021 A | I5: 2022 A | J5: 2023 A | K5: 2024 A | L5: 2025 A | N5: 2026 Q3 | O5: Q3
A7: In Millions of USD except Per Share | C7: ="FY "&LEFT(C5,4) -> FY 2016 | D7: ="FY "&LEFT(D5,4) -> FY 2017 | E7: ="FY "&LEFT(E5,4) -> FY 2018 | F7: ="FY "&LEFT(F5,4) -> FY 2019 | G7: ="FY "&LEFT(G5,4) -> FY 2020 | H7: ="FY "&LEFT(H5,4) -> FY 2021 | I7: ="FY "&LEFT(I5,4) -> FY 2022 | J7: ="FY "&LEFT(J5,4) -> FY 2023 | ... L7: ="FY "&LEFT(L5,4) -> FY 2025
A8: 12 Months Ending | C8: =C4 -> 42613 | D8: =D4 -> 42978 | E8: =E4 -> 43343 | F8: =F4 -> 43708 | G8: =G4 -> 44074 | H8: =H4 -> 44439 | I8: =I4 -> 44804 | J8: =J4 -> 45169 | ... L8: =L4 -> 45900
A9: Total Assets | C9: 499.565 | D9: 506.032 | E9: 500.256 | F9: 500.314 | G9: 570.526 | H9: 637.185 | I9: 710.653 | J9: 745.66 | K9: 760.232 | L9: 840.836
A10: + Cash, Cash Equivalents & STI | B10: C&CE_AND_STI_DETAILED | C10: 101.246 | D10: 121.62 | E10: 160.787 | F10: 127.204 | G10: 140.914 | H10: 146.711 | I10: 116.508 | J10: 166.311 | K10: 190.879 | L10: 250.575 | M10: =IF(OR(K10=0,K10=""),"",L10/K10-1) -> 0.31274263
A11: + Cash & Cash Equivalents | B11: BS_CASH_NEAR_CASH_ITEM | C11: 101.246 | D11: 121.62 | E11: 160.787 | F11: 127.204 | G11: 121.403 | H11: 127.107 | I11: 105.048 | J11: 160.755 | K11: 190.879 | L11: 250.575
A12: + ST Investments | B12: BS_MKT_SEC_OTHER_ST_INVEST | C12: 0 | D12: 0 | E12: 0 | F12: 0 | G12: 19.511 | H12: 19.604 | I12: 11.46 | J12: 5.556 | K12: 0 | L12: 0
A13: check | C13: =ROUND(SUM(C11:C12)-IF(C10="",0,C10),1) -> 0 | D13: =ROUND(SUM(D11:D12)-IF(D10="",0,D10),1) -> 0 | E13: =ROUND(SUM(E11:E12)-IF(E10="",0,E10),1) -> 0 | F13: =ROUND(SUM(F11:F12)-IF(F10="",0,F10),1) -> 0 | G13: =ROUND(SUM(G11:G12)-IF(G10="",0,G10),1) -> 0 | H13: =ROUND(SUM(H11:H12)-IF(H10="",0,H10),1) -> 0 | I13: =ROUND(SUM(I11:I12)-IF(I10="",0,I10),1) -> 0 | J13: =ROUND(SUM(J11:J12)-IF(J10="",0,J10),1) -> 0 | ... L13: =ROUND(SUM(L11:L12)-IF(L10="",0,L10),1) -> 0
A14: + Accounts & Notes Receiv | B14: BS_ACCT_NOTE_RCV | C14: 80.61 | D14: 73.85 | E14: 69.107 | F14: 75.551 | G14: 84.604 | H14: 93.609 | I14: 138.2 | J14: 144.774 | K14: 116.601 | L14: 113.027 | M14: =IF(OR(K14=0,K14=""),"",L14/K14-1) -> -0.030651538
A15: + Accounts Receivable, Net | B15: BS_ACCTS_REC_EXCL_NOTES_REC | C15: 80.61 | D15: 73.85 | E15: 69.107 | F15: 75.551 | G15: 84.604 | H15: 93.609 | I15: 138.2 | J15: 144.774 | K15: 116.601 | L15: 113.027
A16: + Notes Receivable, Net | B16: NOTES_RECEIVABLE | C16: 0 | D16: 0 | E16: 0 | F16: 0 | G16: 0 | H16: 0 | I16: 0 | J16: 0 | K16: 0 | L16: 0
A17: check | C17: =IF(AND(C15="",C16=""),0,ROUND(SUM(C15:C16)-IF(C14="",0,C14),1)) -> 0 | D17: =IF(AND(D15="",D16=""),0,ROUND(SUM(D15:D16)-IF(D14="",0,D14),1)) -> 0 | E17: =IF(AND(E15="",E16=""),0,ROUND(SUM(E15:E16)-IF(E14="",0,E14),1)) -> 0 | F17: =IF(AND(F15="",F16=""),0,ROUND(SUM(F15:F16)-IF(F14="",0,F14),1)) -> 0 | G17: =IF(AND(G15="",G16=""),0,ROUND(SUM(G15:G16)-IF(G14="",0,G14),1)) -> 0 | H17: =IF(AND(H15="",H16=""),0,ROUND(SUM(H15:H16)-IF(H14="",0,H14),1)) -> 0 | I17: =IF(AND(I15="",I16=""),0,ROUND(SUM(I15:I16)-IF(I14="",0,I14),1)) -> 0 | J17: =IF(AND(J15="",J16=""),0,ROUND(SUM(J15:J16)-IF(J14="",0,J14),1)) -> 0 | ... L17: =IF(AND(L15="",L16=""),0,ROUND(SUM(L15:L16)-IF(L14="",0,L14),1)) -> 0
A19: + Unbilled Revenues | B19: BS_UNBILLED_REVENUES | M19: =IF(OR(K19=0,K19=""),"",L19/K19-1)
A20: + Inventories | B20: BS_INVENTORIES | C20: 74.75 | D20: 86.155 | E20: 79.233 | F20: 92.287 | G20: 104.792 | H20: 145.244 | I20: 193.776 | J20: 155.932 | K20: 154.453 | L20: 136.859 | M20: =IF(OR(K20=0,K20=""),"",L20/K20-1) -> -0.11391168
A21: + Raw Materials | B21: INVTRY_RAW_MATERIALS | C21: 26.599 | D21: 31.158 | E21: 36.316 | F21: 49.047 | G21: 51.205 | H21: 69.962 | I21: 93.469 | J21: 83.908 | K21: 84.725 | L21: 70.51
A22: + Work In Process | B22: INVTRY_IN_PROGRESS | C22: 5.742 | D22: 7.113 | E22: 9.176 | F22: 4.514 | G22: 6.464 | H22: 8.301 | I22: 12.603 | J22: 7.82 | K22: 10.192 | L22: 7.186
A23: + Finished Goods | B23: INVTRY_FINISHED_GOODS | C23: 47.805 | D23: 52.382 | E23: 40.197 | F23: 46.812 | G23: 51.684 | H23: 75.053 | I23: 110.022 | J23: 86.793 | K23: 80.877 | L23: 78.631
A24: + Other Inventory | B24: BS_OTHER_INV | C24: -5.396 | D24: -4.498 | E24: -6.456 | F24: -8.086 | G24: -4.561 | H24: -8.072 | I24: -22.318 | J24: -22.589 | K24: -21.341 | L24: -19.468
A25: check | C25: =IF(AND(C21="",C22="",C23="",C24=""),0,ROUND(SUM(C21:C24)-IF(C20="",0,C20),1)) -> 0 | D25: =IF(AND(D21="",D22="",D23="",D24=""),0,ROUND(SUM(D21:D24)-IF(D20="",0,D20),1)) -> 0 | E25: =IF(AND(E21="",E22="",E23="",E24=""),0,ROUND(SUM(E21:E24)-IF(E20="",0,E20),1)) -> 0 | F25: =IF(AND(F21="",F22="",F23="",F24=""),0,ROUND(SUM(F21:F24)-IF(F20="",0,F20),1)) -> 0 | G25: =IF(AND(G21="",G22="",G23="",G24=""),0,ROUND(SUM(G21:G24)-IF(G20="",0,G20),1)) -> 0 | H25: =IF(AND(H21="",H22="",H23="",H24=""),0,ROUND(SUM(H21:H24)-IF(H20="",0,H20),1)) -> 0 | I25: =IF(AND(I21="",I22="",I23="",I24=""),0,ROUND(SUM(I21:I24)-IF(I20="",0,I20),1)) -> 0 | J25: =IF(AND(J21="",J22="",J23="",J24=""),0,ROUND(SUM(J21:J24)-IF(J20="",0,J20),1)) -> 0 | ... L25: =IF(AND(L21="",L22="",L23="",L24=""),0,ROUND(SUM(L21:L24)-IF(L20="",0,L20),1)) -> 0
A26: + Other ST Assets | B26: OTHER_CURRENT_ASSETS_DETAILED | C26: 20.169 | D26: 11.309 | E26: 21.924 | F26: 18.448 | G26: 17.625 | H26: 30.539 | I26: 28.617 | J26: 20.467 | K26: 31.279 | L26: 32.303 | M26: =IF(OR(K26=0,K26=""),"",L26/K26-1) -> 0.032737619
A27: + Prepaid Expenses | B27: BS_PREPAY | C27: 3.671 | D27: 4.384 | E27: 3.883
A28: + ST Derivative & Hedging Assets | B28: BS_DERIV_&_HEDGING_ASSETS_ST | C28: 0.073 | D28: 0.009 | E28: 0.898 | F28: 1.112 | G28: 0.021 | H28: 0 | I28: 0 | J28: 0 | L28: 0
A29: + Assets Held-for-Sale | B29: BS_ASSETS_HELD_FOR_SALE_ST | E29: 10.837 | F29: 2.744 | G29: 0 | H29: 0 | I29: 0
A30: + ST Deferred Tax Assets | B30: BS_DEFERRED_TAX_ASSETS_ST
A31: + Taxes Receivable | B31: BS_TAXES_RECEIVABLE_SHORT_TERM
A32: + Assets of Discontinued Operations ST | B32: BS_ASSETS_OF_DISCONTINUED_OPS_ST
A33: + Misc ST Assets | B33: BS_OTHER_CUR_ASSET_LESS_PREPAY | C33: 16.425 | D33: 6.916 | E33: 6.306 | F33: 14.592 | G33: 17.604 | H33: 30.539 | I33: 28.617 | J33: 20.467 | K33: 31.279 | L33: 32.303
A34: check | C34: =ROUND(SUM(C27:C33)-IF(C26="",0,C26),1) -> 0 | D34: =ROUND(SUM(D27:D33)-IF(D26="",0,D26),1) -> 0 | E34: =ROUND(SUM(E27:E33)-IF(E26="",0,E26),1) -> 0 | F34: =ROUND(SUM(F27:F33)-IF(F26="",0,F26),1) -> 0 | G34: =ROUND(SUM(G27:G33)-IF(G26="",0,G26),1) -> 0 | H34: =ROUND(SUM(H27:H33)-IF(H26="",0,H26),1) -> 0 | I34: =ROUND(SUM(I27:I33)-IF(I26="",0,I26),1) -> 0 | J34: =ROUND(SUM(J27:J33)-IF(J26="",0,J26),1) -> 0 | ... L34: =ROUND(SUM(L27:L33)-IF(L26="",0,L26),1) -> 0
A35: Total Current Assets | B35: BS_CUR_ASSET_REPORT | C35: 276.775 | D35: 292.934 | E35: 331.051 | F35: 313.49 | G35: 347.935 | H35: 416.103 | I35: 477.101 | J35: 487.484 | K35: 493.212 | L35: 532.764 | M35: =IF(OR(K35=0,K35=""),"",L35/K35-1) -> 0.080192696
A36: check | C36: =ROUND(IF(C10="",0,C10)+IF(C14="",0,C14)+IF(C19="",0,C19)+IF(C20="",0,C20)+IF(C26="",0,C26)-IF(C35="",0,C35),1) -> 0 | D36: =ROUND(IF(D10="",0,D10)+IF(D14="",0,D14)+IF(D19="",0,D19)+IF(D20="",0,D20)+IF(D26="",0,D26)-IF(D35="",0,D35),1) -> 0 | E36: =ROUND(IF(E10="",0,E10)+IF(E14="",0,E14)+IF(E19="",0,E19)+IF(E20="",0,E20)+IF(E26="",0,E26)-IF(E35="",0,E35),1) -> 0 | F36: =ROUND(IF(F10="",0,F10)+IF(F14="",0,F14)+IF(F19="",0,F19)+IF(F20="",0,F20)+IF(F26="",0,F26)-IF(F35="",0,F35),1) -> 0 | G36: =ROUND(IF(G10="",0,G10)+IF(G14="",0,G14)+IF(G19="",0,G19)+IF(G20="",0,G20)+IF(G26="",0,G26)-IF(G35="",0,G35),1) -> 0 | H36: =ROUND(IF(H10="",0,H10)+IF(H14="",0,H14)+IF(H19="",0,H19)+IF(H20="",0,H20)+IF(H26="",0,H26)-IF(H35="",0,H35),1) -> 0 | I36: =ROUND(IF(I10="",0,I10)+IF(I14="",0,I14)+IF(I19="",0,I19)+IF(I20="",0,I20)+IF(I26="",0,I26)-IF(I35="",0,I35),1) -> 0 | J36: =ROUND(IF(J10="",0,J10)+IF(J14="",0,J14)+IF(J19="",0,J19)+IF(J20="",0,J20)+IF(J26="",0,J26)-IF(J35="",0,J35),1) -> 0 | ... L36: =ROUND(IF(L10="",0,L10)+IF(L14="",0,L14)+IF(L19="",0,L19)+IF(L20="",0,L20)+IF(L26="",0,L26)-IF(L35="",0,L35),1) -> 0
A37: + Property, Plant & Equip, Net (As Reported) | B37: ARD_PROPERTY_PLANT_EQUIP_NET | C37: 77.627 | D37: 74.498 | E37: 57.248 | F37: 68.968 | G37: 79.581 | H37: 91.997 | I37: 94.472 | J37: 99.681 | K37: 112.815 | L37: 142.307 | M37: =IF(OR(K37=0,K37=""),"",L37/K37-1) -> 0.26141914
A38: + Property, Plant & Equip, Net (Standardized) | B38: BS_NET_FIX_ASSET | C38: 77.627 | D38: 74.498 | E38: 57.248 | F38: 68.968 | G38: 107.038 | H38: 110.278 | I38: 113.653 | J38: 116.717 | K38: 128.508 | L38: 160.403
A39: + Property, Plant & Equip (Standardized) | B39: BS_GROSS_FIX_ASSET | C39: 182.696 | D39: 189.14 | E39: 171.45 | F39: 188.695 | G39: 235.564 | H39: 247.281 | I39: 260.162 | J39: 274.777 | K39: 296.308 | L39: 333.156
A40: - Accumulated Depreciation (Standardized) | B40: BS_ACCUM_DEPR | C40: 105.069 | D40: 114.642 | E40: 114.202 | F40: 119.727 | G40: 128.526 | H40: 137.003 | I40: 146.509 | J40: 158.06 | K40: 167.8 | L40: 172.753
A41: Operating Leases | C41: =IF(C38="",0,C38)-IF(C37="",0,C37) -> 0 | D41: =IF(D38="",0,D38)-IF(D37="",0,D37) -> 0 | E41: =IF(E38="",0,E38)-IF(E37="",0,E37) -> 0 | F41: =IF(F38="",0,F38)-IF(F37="",0,F37) -> 0 | G41: =IF(G38="",0,G38)-IF(G37="",0,G37) -> 27.457 | H41: =IF(H38="",0,H38)-IF(H37="",0,H37) -> 18.281 | I41: =IF(I38="",0,I38)-IF(I37="",0,I37) -> 19.181 | J41: =IF(J38="",0,J38)-IF(J37="",0,J37) -> 17.036 | ... L41: =IF(L38="",0,L38)-IF(L37="",0,L37) -> 18.096
A42: check | C42: =ROUND(IF(C39="",0,C39)-IF(C40="",0,C40)-IF(C38="",0,C38),1) -> 0 | D42: =ROUND(IF(D39="",0,D39)-IF(D40="",0,D40)-IF(D38="",0,D38),1) -> 0 | E42: =ROUND(IF(E39="",0,E39)-IF(E40="",0,E40)-IF(E38="",0,E38),1) -> 0 | F42: =ROUND(IF(F39="",0,F39)-IF(F40="",0,F40)-IF(F38="",0,F38),1) -> 0 | G42: =ROUND(IF(G39="",0,G39)-IF(G40="",0,G40)-IF(G38="",0,G38),1) -> 0 | H42: =ROUND(IF(H39="",0,H39)-IF(H40="",0,H40)-IF(H38="",0,H38),1) -> 0 | I42: =ROUND(IF(I39="",0,I39)-IF(I40="",0,I40)-IF(I38="",0,I38),1) -> 0 | J42: =ROUND(IF(J39="",0,J39)-IF(J40="",0,J40)-IF(J38="",0,J38),1) -> 0 | ... L42: =ROUND(IF(L39="",0,L39)-IF(L40="",0,L40)-IF(L38="",0,L38),1) -> 0
...

Sheet BS%
A1: ='Balance Sheet - Standardized'!A1 -> Ticker | C1: =IF('Balance Sheet - Standardized'!C1="","",'Balance Sheet - Standardized'!C1) -> LNN
A2: ='Balance Sheet - Standardized'!A2 -> Start Year | C2: ='Balance Sheet - Standardized'!C2 -> FY 2016
A3: ='Balance Sheet - Standardized'!A3 -> End Year
C4: ='Balance Sheet - Standardized'!C4 -> 42613 | D4: ='Balance Sheet - Standardized'!D4 -> 42978 | E4: ='Balance Sheet - Standardized'!E4 -> 43343 | F4: ='Balance Sheet - Standardized'!F4 -> 43708 | G4: ='Balance Sheet - Standardized'!G4 -> 44074 | H4: ='Balance Sheet - Standardized'!H4 -> 44439 | I4: ='Balance Sheet - Standardized'!I4 -> 44804 | J4: ='Balance Sheet - Standardized'!J4 -> 45169 | ... L4: ='Balance Sheet - Standardized'!L4 -> 45900
C5: ='Balance Sheet - Standardized'!C5 -> 2016 A | D5: ='Balance Sheet - Standardized'!D5 -> 2017 A | E5: ='Balance Sheet - Standardized'!E5 -> 2018 A | F5: ='Balance Sheet - Standardized'!F5 -> 2019 A | G5: ='Balance Sheet - Standardized'!G5 -> 2020 A | H5: ='Balance Sheet - Standardized'!H5 -> 2021 A | I5: ='Balance Sheet - Standardized'!I5 -> 2022 A | J5: ='Balance Sheet - Standardized'!J5 -> 2023 A | ... L5: ='Balance Sheet - Standardized'!L5 -> 2025 A
A7: ='Balance Sheet - Standardized'!A7 -> In Millions of USD except Per Share | C7: ='Balance Sheet - Standardized'!C7 -> FY 2016 | D7: ='Balance Sheet - Standardized'!D7 -> FY 2017 | E7: ='Balance Sheet - Standardized'!E7 -> FY 2018 | F7: ='Balance Sheet - Standardized'!F7 -> FY 2019 | G7: ='Balance Sheet - Standardized'!G7 -> FY 2020 | H7: ='Balance Sheet - Standardized'!H7 -> FY 2021 | I7: ='Balance Sheet - Standardized'!I7 -> FY 2022 | J7: ='Balance Sheet - Standardized'!J7 -> FY 2023 | ... L7: ='Balance Sheet - Standardized'!L7 -> FY 2025
A8: ='Balance Sheet - Standardized'!A8 -> 12 Months Ending | C8: ='Balance Sheet - Standardized'!C8 -> 42613 | D8: ='Balance Sheet - Standardized'!D8 -> 42978 | E8: ='Balance Sheet - Standardized'!E8 -> 43343 | F8: ='Balance Sheet - Standardized'!F8 -> 43708 | G8: ='Balance Sheet - Standardized'!G8 -> 44074 | H8: ='Balance Sheet - Standardized'!H8 -> 44439 | I8: ='Balance Sheet - Standardized'!I8 -> 44804 | J8: ='Balance Sheet - Standardized'!J8 -> 45169 | ... L8: ='Balance Sheet - Standardized'!L8 -> 45900
A9: ='Balance Sheet - Standardized'!A9 -> Total Assets
A10: ='Balance Sheet - Standardized'!A10 -> + Cash, Cash Equivalents & STI | B10: ='Balance Sheet - Standardized'!B10 -> C&CE_AND_STI_DETAILED | C10: =IF('Balance Sheet - Standardized'!C10="",0,'Balance Sheet - Standardized'!C10)/'Balance Sheet - Standardized'!C$61 -> 0.20767771 | D10: =IF('Balance Sheet - Standardized'!D10="",0,'Balance Sheet - Standardized'!D10)/'Balance Sheet - Standardized'!D$61 -> 0.24034053 | E10: =IF('Balance Sheet - Standardized'!E10="",0,'Balance Sheet - Standardized'!E10)/'Balance Sheet - Standardized'!E$61 -> 0.32140944 | F10: =IF('Balance Sheet - Standardized'!F10="",0,'Balance Sheet - Standardized'!F10)/'Balance Sheet - Standardized'!F$61 -> 0.25424833 | G10: =IF('Balance Sheet - Standardized'!G10="",0,'Balance Sheet - Standardized'!G10)/'Balance Sheet - Standardized'!G$61 -> 0.24698962 | H10: =IF('Balance Sheet - Standardized'!H10="",0,'Balance Sheet - Standardized'!H10)/'Balance Sheet - Standardized'!H$61 -> 0.23024867 | I10: =IF('Balance Sheet - Standardized'!I10="",0,'Balance Sheet - Standardized'!I10)/'Balance Sheet - Standardized'!I$61 -> 0.16394499 | J10: =IF('Balance Sheet - Standardized'!J10="",0,'Balance Sheet - Standardized'!J10)/'Balance Sheet - Standardized'!J$61 -> 0.22303865 | ... L10: =IF('Balance Sheet - Standardized'!L10="",0,'Balance Sheet - Standardized'!L10)/'Balance Sheet - Standardized'!L$61 -> 0.29800698
A11: ='Balance Sheet - Standardized'!A11 -> + Cash & Cash Equivalents | B11: ='Balance Sheet - Standardized'!B11 -> BS_CASH_NEAR_CASH_ITEM | C11: =IF('Balance Sheet - Standardized'!C11="",0,'Balance Sheet - Standardized'!C11)/'Balance Sheet - Standardized'!C$61 -> 0.20767771 | D11: =IF('Balance Sheet - Standardized'!D11="",0,'Balance Sheet - Standardized'!D11)/'Balance Sheet - Standardized'!D$61 -> 0.24034053 | E11: =IF('Balance Sheet - Standardized'!E11="",0,'Balance Sheet - Standardized'!E11)/'Balance Sheet - Standardized'!E$61 -> 0.32140944 | F11: =IF('Balance Sheet - Standardized'!F11="",0,'Balance Sheet - Standardized'!F11)/'Balance Sheet - Standardized'!F$61 -> 0.25424833 | G11: =IF('Balance Sheet - Standardized'!G11="",0,'Balance Sheet - Standardized'!G11)/'Balance Sheet - Standardized'!G$61 -> 0.21279135 | H11: =IF('Balance Sheet - Standardized'!H11="",0,'Balance Sheet - Standardized'!H11)/'Balance Sheet - Standardized'!H$61 -> 0.1994821 | I11: =IF('Balance Sheet - Standardized'!I11="",0,'Balance Sheet - Standardized'!I11)/'Balance Sheet - Standardized'!I$61 -> 0.14781898 | J11: =IF('Balance Sheet - Standardized'!J11="",0,'Balance Sheet - Standardized'!J11)/'Balance Sheet - Standardized'!J$61 -> 0.21558753 | ... L11: =IF('Balance Sheet - Standardized'!L11="",0,'Balance Sheet - Standardized'!L11)/'Balance Sheet - Standardized'!L$61 -> 0.29800698
A12: ='Balance Sheet - Standardized'!A12 -> + ST Investments | B12: ='Balance Sheet - Standardized'!B12 -> BS_MKT_SEC_OTHER_ST_INVEST | C12: =IF('Balance Sheet - Standardized'!C12="",0,'Balance Sheet - Standardized'!C12)/'Balance Sheet - Standardized'!C$61 -> 0 | D12: =IF('Balance Sheet - Standardized'!D12="",0,'Balance Sheet - Standardized'!D12)/'Balance Sheet - Standardized'!D$61 -> 0 | E12: =IF('Balance Sheet - Standardized'!E12="",0,'Balance Sheet - Standardized'!E12)/'Balance Sheet - Standardized'!E$61 -> 0 | F12: =IF('Balance Sheet - Standardized'!F12="",0,'Balance Sheet - Standardized'!F12)/'Balance Sheet - Standardized'!F$61 -> 0 | G12: =IF('Balance Sheet - Standardized'!G12="",0,'Balance Sheet - Standardized'!G12)/'Balance Sheet - Standardized'!G$61 -> 0.034198266 | H12: =IF('Balance Sheet - Standardized'!H12="",0,'Balance Sheet - Standardized'!H12)/'Balance Sheet - Standardized'!H$61 -> 0.030766575 | I12: =IF('Balance Sheet - Standardized'!I12="",0,'Balance Sheet - Standardized'!I12)/'Balance Sheet - Standardized'!I$61 -> 0.016126014 | J12: =IF('Balance Sheet - Standardized'!J12="",0,'Balance Sheet - Standardized'!J12)/'Balance Sheet - Standardized'!J$61 -> 0.0074511171 | ... L12: =IF('Balance Sheet - Standardized'!L12="",0,'Balance Sheet - Standardized'!L12)/'Balance Sheet - Standardized'!L$61 -> 0
A13: ='Balance Sheet - Standardized'!A13 -> check
A14: ='Balance Sheet - Standardized'!A14 -> + Accounts & Notes Receiv | B14: ='Balance Sheet - Standardized'!B14 -> BS_ACCT_NOTE_RCV | C14: =IF('Balance Sheet - Standardized'!C14="",0,'Balance Sheet - Standardized'!C14)/'Balance Sheet - Standardized'!C$61 -> 0.16534876 | D14: =IF('Balance Sheet - Standardized'!D14="",0,'Balance Sheet - Standardized'!D14)/'Balance Sheet - Standardized'!D$61 -> 0.14593939 | E14: =IF('Balance Sheet - Standardized'!E14="",0,'Balance Sheet - Standardized'!E14)/'Balance Sheet - Standardized'!E$61 -> 0.13814327 | F14: =IF('Balance Sheet - Standardized'!F14="",0,'Balance Sheet - Standardized'!F14)/'Balance Sheet - Standardized'!F$61 -> 0.15100717 | G14: =IF('Balance Sheet - Standardized'!G14="",0,'Balance Sheet - Standardized'!G14)/'Balance Sheet - Standardized'!G$61 -> 0.14829123 | H14: =IF('Balance Sheet - Standardized'!H14="",0,'Balance Sheet - Standardized'!H14)/'Balance Sheet - Standardized'!H$61 -> 0.14691024 | I14: =IF('Balance Sheet - Standardized'!I14="",0,'Balance Sheet - Standardized'!I14)/'Balance Sheet - Standardized'!I$61 -> 0.19446903 | J14: =IF('Balance Sheet - Standardized'!J14="",0,'Balance Sheet - Standardized'!J14)/'Balance Sheet - Standardized'!J$61 -> 0.19415551 | ... L14: =IF('Balance Sheet - Standardized'!L14="",0,'Balance Sheet - Standardized'!L14)/'Balance Sheet - Standardized'!L$61 -> 0.13442217
A15: ='Balance Sheet - Standardized'!A15 -> + Accounts Receivable, Net | B15: ='Balance Sheet - Standardized'!B15 -> BS_ACCTS_REC_EXCL_NOTES_REC | C15: =IF('Balance Sheet - Standardized'!C15="",0,'Balance Sheet - Standardized'!C15)/'Balance Sheet - Standardized'!C$61 -> 0.16534876 | D15: =IF('Balance Sheet - Standardized'!D15="",0,'Balance Sheet - Standardized'!D15)/'Balance Sheet - Standardized'!D$61 -> 0.14593939 | E15: =IF('Balance Sheet - Standardized'!E15="",0,'Balance Sheet - Standardized'!E15)/'Balance Sheet - Standardized'!E$61 -> 0.13814327 | F15: =IF('Balance Sheet - Standardized'!F15="",0,'Balance Sheet - Standardized'!F15)/'Balance Sheet - Standardized'!F$61 -> 0.15100717 | G15: =IF('Balance Sheet - Standardized'!G15="",0,'Balance Sheet - Standardized'!G15)/'Balance Sheet - Standardized'!G$61 -> 0.14829123 | H15: =IF('Balance Sheet - Standardized'!H15="",0,'Balance Sheet - Standardized'!H15)/'Balance Sheet - Standardized'!H$61 -> 0.14691024 | I15: =IF('Balance Sheet - Standardized'!I15="",0,'Balance Sheet - Standardized'!I15)/'Balance Sheet - Standardized'!I$61 -> 0.19446903 | J15: =IF('Balance Sheet - Standardized'!J15="",0,'Balance Sheet - Standardized'!J15)/'Balance Sheet - Standardized'!J$61 -> 0.19415551 | ... L15: =IF('Balance Sheet - Standardized'!L15="",0,'Balance Sheet - Standardized'!L15)/'Balance Sheet - Standardized'!L$61 -> 0.13442217
A16: ='Balance Sheet - Standardized'!A16 -> + Notes Receivable, Net | B16: ='Balance Sheet - Standardized'!B16 -> NOTES_RECEIVABLE | C16: =IF('Balance Sheet - Standardized'!C16="",0,'Balance Sheet - Standardized'!C16)/'Balance Sheet - Standardized'!C$61 -> 0 | D16: =IF('Balance Sheet - Standardized'!D16="",0,'Balance Sheet - Standardized'!D16)/'Balance Sheet - Standardized'!D$61 -> 0 | E16: =IF('Balance Sheet - Standardized'!E16="",0,'Balance Sheet - Standardized'!E16)/'Balance Sheet - Standardized'!E$61 -> 0 | F16: =IF('Balance Sheet - Standardized'!F16="",0,'Balance Sheet - Standardized'!F16)/'Balance Sheet - Standardized'!F$61 -> 0 | G16: =IF('Balance Sheet - Standardized'!G16="",0,'Balance Sheet - Standardized'!G16)/'Balance Sheet - Standardized'!G$61 -> 0 | H16: =IF('Balance Sheet - Standardized'!H16="",0,'Balance Sheet - Standardized'!H16)/'Balance Sheet - Standardized'!H$61 -> 0 | I16: =IF('Balance Sheet - Standardized'!I16="",0,'Balance Sheet - Standardized'!I16)/'Balance Sheet - Standardized'!I$61 -> 0 | J16: =IF('Balance Sheet - Standardized'!J16="",0,'Balance Sheet - Standardized'!J16)/'Balance Sheet - Standardized'!J$61 -> 0 | ... L16: =IF('Balance Sheet - Standardized'!L16="",0,'Balance Sheet - Standardized'!L16)/'Balance Sheet - Standardized'!L$61 -> 0
A17: ='Balance Sheet - Standardized'!A17 -> check
A18: ='Balance Sheet - Standardized'!A20 -> + Inventories | B18: ='Balance Sheet - Standardized'!B20 -> BS_INVENTORIES | C18: =IF('Balance Sheet - Standardized'!C20="",0,'Balance Sheet - Standardized'!C20)/'Balance Sheet - Standardized'!C$61 -> 0.15332862 | D18: =IF('Balance Sheet - Standardized'!D20="",0,'Balance Sheet - Standardized'!D20)/'Balance Sheet - Standardized'!D$61 -> 0.17025603 | E18: =IF('Balance Sheet - Standardized'!E20="",0,'Balance Sheet - Standardized'!E20)/'Balance Sheet - Standardized'!E$61 -> 0.15838491 | F18: =IF('Balance Sheet - Standardized'!F20="",0,'Balance Sheet - Standardized'!F20)/'Balance Sheet - Standardized'!F$61 -> 0.18445816 | G18: =IF('Balance Sheet - Standardized'!G20="",0,'Balance Sheet - Standardized'!G20)/'Balance Sheet - Standardized'!G$61 -> 0.18367612 | H18: =IF('Balance Sheet - Standardized'!H20="",0,'Balance Sheet - Standardized'!H20)/'Balance Sheet - Standardized'!H$61 -> 0.22794636 | I18: =IF('Balance Sheet - Standardized'!I20="",0,'Balance Sheet - Standardized'!I20)/'Balance Sheet - Standardized'!I$61 -> 0.27267316 | J18: =IF('Balance Sheet - Standardized'!J20="",0,'Balance Sheet - Standardized'!J20)/'Balance Sheet - Standardized'!J$61 -> 0.20911944 | ... L18: =IF('Balance Sheet - Standardized'!L20="",0,'Balance Sheet - Standardized'!L20)/'Balance Sheet - Standardized'!L$61 -> 0.16276539
A19: ='Balance Sheet - Standardized'!A21 -> + Raw Materials | B19: ='Balance Sheet - Standardized'!B21 -> INVTRY_RAW_MATERIALS | C19: =IF('Balance Sheet - Standardized'!C21="",0,'Balance Sheet - Standardized'!C21)/'Balance Sheet - Standardized'!C$61 -> 0.054560373 | D19: =IF('Balance Sheet - Standardized'!D21="",0,'Balance Sheet - Standardized'!D21)/'Balance Sheet - Standardized'!D$61 -> 0.061573181 | E19: =IF('Balance Sheet - Standardized'!E21="",0,'Balance Sheet - Standardized'!E21)/'Balance Sheet - Standardized'!E$61 -> 0.072594831 | F19: =IF('Balance Sheet - Standardized'!F21="",0,'Balance Sheet - Standardized'!F21)/'Balance Sheet - Standardized'!F$61 -> 0.098032436 | G19: =IF('Balance Sheet - Standardized'!G21="",0,'Balance Sheet - Standardized'!G21)/'Balance Sheet - Standardized'!G$61 -> 0.089750511 | H19: =IF('Balance Sheet - Standardized'!H21="",0,'Balance Sheet - Standardized'!H21)/'Balance Sheet - Standardized'!H$61 -> 0.10979857 | I19: =IF('Balance Sheet - Standardized'!I21="",0,'Balance Sheet - Standardized'!I21)/'Balance Sheet - Standardized'!I$61 -> 0.13152551 | J19: =IF('Balance Sheet - Standardized'!J21="",0,'Balance Sheet - Standardized'!J21)/'Balance Sheet - Standardized'!J$61 -> 0.1125285 | ... L19: =IF('Balance Sheet - Standardized'!L21="",0,'Balance Sheet - Standardized'!L21)/'Balance Sheet - Standardized'!L$61 -> 0.083857018
A20: ='Balance Sheet - Standardized'!A22 -> + Work In Process | B20: ='Balance Sheet - Standardized'!B22 -> INVTRY_IN_PROGRESS | C20: =IF('Balance Sheet - Standardized'!C22="",0,'Balance Sheet - Standardized'!C22)/'Balance Sheet - Standardized'!C$61 -> 0.011778099 | D20: =IF('Balance Sheet - Standardized'!D22="",0,'Balance Sheet - Standardized'!D22)/'Balance Sheet - Standardized'!D$61 -> 0.014056423 | E20: =IF('Balance Sheet - Standardized'!E22="",0,'Balance Sheet - Standardized'!E22)/'Balance Sheet - Standardized'!E$61 -> 0.018342609 | F20: =IF('Balance Sheet - Standardized'!F22="",0,'Balance Sheet - Standardized'!F22)/'Balance Sheet - Standardized'!F$61 -> 0.009022334 | G20: =IF('Balance Sheet - Standardized'!G22="",0,'Balance Sheet - Standardized'!G22)/'Balance Sheet - Standardized'!G$61 -> 0.011329896 | H20: =IF('Balance Sheet - Standardized'!H22="",0,'Balance Sheet - Standardized'!H22)/'Balance Sheet - Standardized'!H$61 -> 0.013027614 | I20: =IF('Balance Sheet - Standardized'!I22="",0,'Balance Sheet - Standardized'!I22)/'Balance Sheet - Standardized'!I$61 -> 0.017734394 | J20: =IF('Balance Sheet - Standardized'!J22="",0,'Balance Sheet - Standardized'!J22)/'Balance Sheet - Standardized'!J$61 -> 0.010487353 | ... L20: =IF('Balance Sheet - Standardized'!L22="",0,'Balance Sheet - Standardized'!L22)/'Balance Sheet - Standardized'!L$61 -> 0.0085462563
A21: ='Balance Sheet - Standardized'!A23 -> + Finished Goods | B21: ='Balance Sheet - Standardized'!B23 -> INVTRY_FINISHED_GOODS | C21: =IF('Balance Sheet - Standardized'!C23="",0,'Balance Sheet - Standardized'!C23)/'Balance Sheet - Standardized'!C$61 -> 0.098058521 | D21: =IF('Balance Sheet - Standardized'!D23="",0,'Balance Sheet - Standardized'!D23)/'Balance Sheet - Standardized'!D$61 -> 0.10351519 | E21: =IF('Balance Sheet - Standardized'!E23="",0,'Balance Sheet - Standardized'!E23)/'Balance Sheet - Standardized'!E$61 -> 0.080352859 | F21: =IF('Balance Sheet - Standardized'!F23="",0,'Balance Sheet - Standardized'!F23)/'Balance Sheet - Standardized'!F$61 -> 0.093565241 | G21: =IF('Balance Sheet - Standardized'!G23="",0,'Balance Sheet - Standardized'!G23)/'Balance Sheet - Standardized'!G$61 -> 0.090590087 | H21: =IF('Balance Sheet - Standardized'!H23="",0,'Balance Sheet - Standardized'!H23)/'Balance Sheet - Standardized'!H$61 -> 0.1177884 | I21: =IF('Balance Sheet - Standardized'!I23="",0,'Balance Sheet - Standardized'!I23)/'Balance Sheet - Standardized'!I$61 -> 0.15481817 | J21: =IF('Balance Sheet - Standardized'!J23="",0,'Balance Sheet - Standardized'!J23)/'Balance Sheet - Standardized'!J$61 -> 0.11639755 | ... L21: =IF('Balance Sheet - Standardized'!L23="",0,'Balance Sheet - Standardized'!L23)/'Balance Sheet - Standardized'!L$61 -> 0.093515263
A22: ='Balance Sheet - Standardized'!A24 -> + Other Inventory | B22: ='Balance Sheet - Standardized'!B24 -> BS_OTHER_INV | C22: =IF('Balance Sheet - Standardized'!C24="",0,'Balance Sheet - Standardized'!C24)/'Balance Sheet - Standardized'!C$61 -> -0.011068377 | D22: =IF('Balance Sheet - Standardized'!D24="",0,'Balance Sheet - Standardized'!D24)/'Balance Sheet - Standardized'!D$61 -> -0.0088887659 | E22: =IF('Balance Sheet - Standardized'!E24="",0,'Balance Sheet - Standardized'!E24)/'Balance Sheet - Standardized'!E$61 -> -0.012905392 | F22: =IF('Balance Sheet - Standardized'!F24="",0,'Balance Sheet - Standardized'!F24)/'Balance Sheet - Standardized'!F$61 -> -0.01616185 | G22: =IF('Balance Sheet - Standardized'!G24="",0,'Balance Sheet - Standardized'!G24)/'Balance Sheet - Standardized'!G$61 -> -0.0079943771 | H22: =IF('Balance Sheet - Standardized'!H24="",0,'Balance Sheet - Standardized'!H24)/'Balance Sheet - Standardized'!H$61 -> -0.01266822 | I22: =IF('Balance Sheet - Standardized'!I24="",0,'Balance Sheet - Standardized'!I24)/'Balance Sheet - Standardized'!I$61 -> -0.031404919 | J22: =IF('Balance Sheet - Standardized'!J24="",0,'Balance Sheet - Standardized'!J24)/'Balance Sheet - Standardized'!J$61 -> -0.030293968 | ... L22: =IF('Balance Sheet - Standardized'!L24="",0,'Balance Sheet - Standardized'!L24)/'Balance Sheet - Standardized'!L$61 -> -0.023153148
A23: ='Balance Sheet - Standardized'!A25 -> check
A24: ='Balance Sheet - Standardized'!A26 -> + Other ST Assets | B24: ='Balance Sheet - Standardized'!B26 -> OTHER_CURRENT_ASSETS_DETAILED | C24: =IF('Balance Sheet - Standardized'!C26="",0,'Balance Sheet - Standardized'!C26)/'Balance Sheet - Standardized'!C$61 -> 0.041371035 | D24: =IF('Balance Sheet - Standardized'!D26="",0,'Balance Sheet - Standardized'!D26)/'Balance Sheet - Standardized'!D$61 -> 0.022348389 | E24: =IF('Balance Sheet - Standardized'!E26="",0,'Balance Sheet - Standardized'!E26)/'Balance Sheet - Standardized'!E$61 -> 0.043825561 | F24: =IF('Balance Sheet - Standardized'!F26="",0,'Balance Sheet - Standardized'!F26)/'Balance Sheet - Standardized'!F$61 -> 0.036872844 | G24: =IF('Balance Sheet - Standardized'!G26="",0,'Balance Sheet - Standardized'!G26)/'Balance Sheet - Standardized'!G$61 -> 0.030892545 | H24: =IF('Balance Sheet - Standardized'!H26="",0,'Balance Sheet - Standardized'!H26)/'Balance Sheet - Standardized'!H$61 -> 0.047927996 | I24: =IF('Balance Sheet - Standardized'!I26="",0,'Balance Sheet - Standardized'!I26)/'Balance Sheet - Standardized'!I$61 -> 0.040268598 | J24: =IF('Balance Sheet - Standardized'!J26="",0,'Balance Sheet - Standardized'!J26)/'Balance Sheet - Standardized'!J$61 -> 0.027448167 | ... L24: =IF('Balance Sheet - Standardized'!L26="",0,'Balance Sheet - Standardized'!L26)/'Balance Sheet - Standardized'!L$61 -> 0.038417718
A25: ='Balance Sheet - Standardized'!A27 -> + Prepaid Expenses | B25: ='Balance Sheet - Standardized'!B27 -> BS_PREPAY | C25: =IF('Balance Sheet - Standardized'!C27="",0,'Balance Sheet - Standardized'!C27)/'Balance Sheet - Standardized'!C$61 -> 0.0075300247 | D25: =IF('Balance Sheet - Standardized'!D27="",0,'Balance Sheet - Standardized'!D27)/'Balance Sheet - Standardized'!D$61 -> 0.0086634837 | E25: =IF('Balance Sheet - Standardized'!E27="",0,'Balance Sheet - Standardized'!E27)/'Balance Sheet - Standardized'!E$61 -> 0.0077620258 | F25: =IF('Balance Sheet - Standardized'!F27="",0,'Balance Sheet - Standardized'!F27)/'Balance Sheet - Standardized'!F$61 -> 0 | G25: =IF('Balance Sheet - Standardized'!G27="",0,'Balance Sheet - Standardized'!G27)/'Balance Sheet - Standardized'!G$61 -> 0 | H25: =IF('Balance Sheet - Standardized'!H27="",0,'Balance Sheet - Standardized'!H27)/'Balance Sheet - Standardized'!H$61 -> 0 | I25: =IF('Balance Sheet - Standardized'!I27="",0,'Balance Sheet - Standardized'!I27)/'Balance Sheet - Standardized'!I$61 -> 0 | J25: =IF('Balance Sheet - Standardized'!J27="",0,'Balance Sheet - Standardized'!J27)/'Balance Sheet - Standardized'!J$61 -> 0 | ... L25: =IF('Balance Sheet - Standardized'!L27="",0,'Balance Sheet - Standardized'!L27)/'Balance Sheet - Standardized'!L$61 -> 0
A26: ='Balance Sheet - Standardized'!A28 -> + ST Derivative & Hedging Assets | B26: ='Balance Sheet - Standardized'!B28 -> BS_DERIV_&_HEDGING_ASSETS_ST | C26: =IF('Balance Sheet - Standardized'!C28="",0,'Balance Sheet - Standardized'!C28)/'Balance Sheet - Standardized'!C$61 -> 0.00014973898 | D26: =IF('Balance Sheet - Standardized'!D28="",0,'Balance Sheet - Standardized'!D28)/'Balance Sheet - Standardized'!D$61 -> 1.7785436e-05 | E26: =IF('Balance Sheet - Standardized'!E28="",0,'Balance Sheet - Standardized'!E28)/'Balance Sheet - Standardized'!E$61 -> 0.0017950809 | F26: =IF('Balance Sheet - Standardized'!F28="",0,'Balance Sheet - Standardized'!F28)/'Balance Sheet - Standardized'!F$61 -> 0.0022226042 | G26: =IF('Balance Sheet - Standardized'!G28="",0,'Balance Sheet - Standardized'!G28)/'Balance Sheet - Standardized'!G$61 -> 3.6808138e-05 | H26: =IF('Balance Sheet - Standardized'!H28="",0,'Balance Sheet - Standardized'!H28)/'Balance Sheet - Standardized'!H$61 -> 0 | I26: =IF('Balance Sheet - Standardized'!I28="",0,'Balance Sheet - Standardized'!I28)/'Balance Sheet - Standardized'!I$61 -> 0 | J26: =IF('Balance Sheet - Standardized'!J28="",0,'Balance Sheet - Standardized'!J28)/'Balance Sheet - Standardized'!J$61 -> 0 | ... L26: =IF('Balance Sheet - Standardized'!L28="",0,'Balance Sheet - Standardized'!L28)/'Balance Sheet - Standardized'!L$61 -> 0
A27: ='Balance Sheet - Standardized'!A29 -> + Assets Held-for-Sale | B27: ='Balance Sheet - Standardized'!B29 -> BS_ASSETS_HELD_FOR_SALE_ST | C27: =IF('Balance Sheet - Standardized'!C29="",0,'Balance Sheet - Standardized'!C29)/'Balance Sheet - Standardized'!C$61 -> 0 | D27: =IF('Balance Sheet - Standardized'!D29="",0,'Balance Sheet - Standardized'!D29)/'Balance Sheet - Standardized'!D$61 -> 0 | E27: =IF('Balance Sheet - Standardized'!E29="",0,'Balance Sheet - Standardized'!E29)/'Balance Sheet - Standardized'!E$61 -> 0.021662909 | F27: =IF('Balance Sheet - Standardized'!F29="",0,'Balance Sheet - Standardized'!F29)/'Balance Sheet - Standardized'!F$61 -> 0.0054845557 | G27: =IF('Balance Sheet - Standardized'!G29="",0,'Balance Sheet - Standardized'!G29)/'Balance Sheet - Standardized'!G$61 -> 0 | H27: =IF('Balance Sheet - Standardized'!H29="",0,'Balance Sheet - Standardized'!H29)/'Balance Sheet - Standardized'!H$61 -> 0 | I27: =IF('Balance Sheet - Standardized'!I29="",0,'Balance Sheet - Standardized'!I29)/'Balance Sheet - Standardized'!I$61 -> 0 | J27: =IF('Balance Sheet - Standardized'!J29="",0,'Balance Sheet - Standardized'!J29)/'Balance Sheet - Standardized'!J$61 -> 0 | ... L27: =IF('Balance Sheet - Standardized'!L29="",0,'Balance Sheet - Standardized'!L29)/'Balance Sheet - Standardized'!L$61 -> 0
A28: ='Balance Sheet - Standardized'!A30 -> + ST Deferred Tax Assets | B28: ='Balance Sheet - Standardized'!B30 -> BS_DEFERRED_TAX_ASSETS_ST | C28: =IF('Balance Sheet - Standardized'!C30="",0,'Balance Sheet - Standardized'!C30)/'Balance Sheet - Standardized'!C$61 -> 0 | D28: =IF('Balance Sheet - Standardized'!D30="",0,'Balance Sheet - Standardized'!D30)/'Balance Sheet - Standardized'!D$61 -> 0 | E28: =IF('Balance Sheet - Standardized'!E30="",0,'Balance Sheet - Standardized'!E30)/'Balance Sheet - Standardized'!E$61 -> 0 | F28: =IF('Balance Sheet - Standardized'!F30="",0,'Balance Sheet - Standardized'!F30)/'Balance Sheet - Standardized'!F$61 -> 0 | G28: =IF('Balance Sheet - Standardized'!G30="",0,'Balance Sheet - Standardized'!G30)/'Balance Sheet - Standardized'!G$61 -> 0 | H28: =IF('Balance Sheet - Standardized'!H30="",0,'Balance Sheet - Standardized'!H30)/'Balance Sheet - Standardized'!H$61 -> 0 | I28: =IF('Balance Sheet - Standardized'!I30="",0,'Balance Sheet - Standardized'!I30)/'Balance Sheet - Standardized'!I$61 -> 0 | J28: =IF('Balance Sheet - Standardized'!J30="",0,'Balance Sheet - Standardized'!J30)/'Balance Sheet - Standardized'!J$61 -> 0 | ... L28: =IF('Balance Sheet - Standardized'!L30="",0,'Balance Sheet - Standardized'!L30)/'Balance Sheet - Standardized'!L$61 -> 0
A29: ='Balance Sheet - Standardized'!A31 -> + Taxes Receivable | B29: ='Balance Sheet - Standardized'!B31 -> BS_TAXES_RECEIVABLE_SHORT_TERM | C29: =IF('Balance Sheet - Standardized'!C31="",0,'Balance Sheet - Standardized'!C31)/'Balance Sheet - Standardized'!C$61 -> 0 | D29: =IF('Balance Sheet - Standardized'!D31="",0,'Balance Sheet - Standardized'!D31)/'Balance Sheet - Standardized'!D$61 -> 0 | E29: =IF('Balance Sheet - Standardized'!E31="",0,'Balance Sheet - Standardized'!E31)/'Balance Sheet - Standardized'!E$61 -> 0 | F29: =IF('Balance Sheet - Standardized'!F31="",0,'Balance Sheet - Standardized'!F31)/'Balance Sheet - Standardized'!F$61 -> 0 | G29: =IF('Balance Sheet - Standardized'!G31="",0,'Balance Sheet - Standardized'!G31)/'Balance Sheet - Standardized'!G$61 -> 0 | H29: =IF('Balance Sheet - Standardized'!H31="",0,'Balance Sheet - Standardized'!H31)/'Balance Sheet - Standardized'!H$61 -> 0 | I29: =IF('Balance Sheet - Standardized'!I31="",0,'Balance Sheet - Standardized'!I31)/'Balance Sheet - Standardized'!I$61 -> 0 | J29: =IF('Balance Sheet - Standardized'!J31="",0,'Balance Sheet - Standardized'!J31)/'Balance Sheet - Standardized'!J$61 -> 0 | ... L29: =IF('Balance Sheet - Standardized'!L31="",0,'Balance Sheet - Standardized'!L31)/'Balance Sheet - Standardized'!L$61 -> 0
A30: + Assets of Discontinued Operations ST | B30: ='Balance Sheet - Standardized'!B32 -> BS_ASSETS_OF_DISCONTINUED_OPS_ST | C30: =IF('Balance Sheet - Standardized'!C32="",0,'Balance Sheet - Standardized'!C32)/'Balance Sheet - Standardized'!C$61 -> 0 | D30: =IF('Balance Sheet - Standardized'!D32="",0,'Balance Sheet - Standardized'!D32)/'Balance Sheet - Standardized'!D$61 -> 0 | E30: =IF('Balance Sheet - Standardized'!E32="",0,'Balance Sheet - Standardized'!E32)/'Balance Sheet - Standardized'!E$61 -> 0 | F30: =IF('Balance Sheet - Standardized'!F32="",0,'Balance Sheet - Standardized'!F32)/'Balance Sheet - Standardized'!F$61 -> 0 | G30: =IF('Balance Sheet - Standardized'!G32="",0,'Balance Sheet - Standardized'!G32)/'Balance Sheet - Standardized'!G$61 -> 0 | H30: =IF('Balance Sheet - Standardized'!H32="",0,'Balance Sheet - Standardized'!H32)/'Balance Sheet - Standardized'!H$61 -> 0 | I30: =IF('Balance Sheet - Standardized'!I32="",0,'Balance Sheet - Standardized'!I32)/'Balance Sheet - Standardized'!I$61 -> 0 | J30: =IF('Balance Sheet - Standardized'!J32="",0,'Balance Sheet - Standardized'!J32)/'Balance Sheet - Standardized'!J$61 -> 0 | ... L30: =IF('Balance Sheet - Standardized'!L32="",0,'Balance Sheet - Standardized'!L32)/'Balance Sheet - Standardized'!L$61 -> 0
A31: ='Balance Sheet - Standardized'!A33 -> + Misc ST Assets | B31: ='Balance Sheet - Standardized'!B33 -> BS_OTHER_CUR_ASSET_LESS_PREPAY | C31: =IF('Balance Sheet - Standardized'!C33="",0,'Balance Sheet - Standardized'!C33)/'Balance Sheet - Standardized'!C$61 -> 0.033691271 | D31: =IF('Balance Sheet - Standardized'!D33="",0,'Balance Sheet - Standardized'!D33)/'Balance Sheet - Standardized'!D$61 -> 0.01366712 | E31: =IF('Balance Sheet - Standardized'!E33="",0,'Balance Sheet - Standardized'!E33)/'Balance Sheet - Standardized'!E$61 -> 0.012605546 | F31: =IF('Balance Sheet - Standardized'!F33="",0,'Balance Sheet - Standardized'!F33)/'Balance Sheet - Standardized'!F$61 -> 0.029165684 | G31: =IF('Balance Sheet - Standardized'!G33="",0,'Balance Sheet - Standardized'!G33)/'Balance Sheet - Standardized'!G$61 -> 0.030855737 | H31: =IF('Balance Sheet - Standardized'!H33="",0,'Balance Sheet - Standardized'!H33)/'Balance Sheet - Standardized'!H$61 -> 0.047927996 | I31: =IF('Balance Sheet - Standardized'!I33="",0,'Balance Sheet - Standardized'!I33)/'Balance Sheet - Standardized'!I$61 -> 0.040268598 | J31: =IF('Balance Sheet - Standardized'!J33="",0,'Balance Sheet - Standardized'!J33)/'Balance Sheet - Standardized'!J$61 -> 0.027448167 | ... L31: =IF('Balance Sheet - Standardized'!L33="",0,'Balance Sheet - Standardized'!L33)/'Balance Sheet - Standardized'!L$61 -> 0.038417718
A32: ='Balance Sheet - Standardized'!A34 -> check
A33: ='Balance Sheet - Standardized'!A35 -> Total Current Assets | B33: ='Balance Sheet - Standardized'!B35 -> BS_CUR_ASSET_REPORT | C33: =IF('Balance Sheet - Standardized'!C35="",0,'Balance Sheet - Standardized'!C35)/'Balance Sheet - Standardized'!C$61 -> 0.56772612 | D33: =IF('Balance Sheet - Standardized'!D35="",0,'Balance Sheet - Standardized'!D35)/'Balance Sheet - Standardized'!D$61 -> 0.57888434 | E33: =IF('Balance Sheet - Standardized'!E35="",0,'Balance Sheet - Standardized'!E35)/'Balance Sheet - Standardized'!E$61 -> 0.66176318 | F33: =IF('Balance Sheet - Standardized'!F35="",0,'Balance Sheet - Standardized'!F35)/'Balance Sheet - Standardized'!F$61 -> 0.6265865 | G33: =IF('Balance Sheet - Standardized'!G35="",0,'Balance Sheet - Standardized'!G35)/'Balance Sheet - Standardized'!G$61 -> 0.60984951 | H33: =IF('Balance Sheet - Standardized'!H35="",0,'Balance Sheet - Standardized'!H35)/'Balance Sheet - Standardized'!H$61 -> 0.65303326 | I33: =IF('Balance Sheet - Standardized'!I35="",0,'Balance Sheet - Standardized'!I35)/'Balance Sheet - Standardized'!I$61 -> 0.67135578 | J33: =IF('Balance Sheet - Standardized'!J35="",0,'Balance Sheet - Standardized'!J35)/'Balance Sheet - Standardized'!J$61 -> 0.65376177 | ... L33: =IF('Balance Sheet - Standardized'!L35="",0,'Balance Sheet - Standardized'!L35)/'Balance Sheet - Standardized'!L$61 -> 0.63361226
A34: ='Balance Sheet - Standardized'!A36 -> check
A35: ='Balance Sheet - Standardized'!A37 -> + Property, Plant & Equip, Net (As Reported) | B35: ='Balance Sheet - Standardized'!B37 -> ARD_PROPERTY_PLANT_EQUIP_NET | C35: =IF('Balance Sheet - Standardized'!C37="",0,'Balance Sheet - Standardized'!C37)/'Balance Sheet - Standardized'!C$61 -> 0.15922997 | D35: =IF('Balance Sheet - Standardized'!D37="",0,'Balance Sheet - Standardized'!D37)/'Balance Sheet - Standardized'!D$61 -> 0.14721994 | E35: =IF('Balance Sheet - Standardized'!E37="",0,'Balance Sheet - Standardized'!E37)/'Balance Sheet - Standardized'!E$61 -> 0.11443741 | F35: =IF('Balance Sheet - Standardized'!F37="",0,'Balance Sheet - Standardized'!F37)/'Balance Sheet - Standardized'!F$61 -> 0.13784943 | G35: =IF('Balance Sheet - Standardized'!G37="",0,'Balance Sheet - Standardized'!G37)/'Balance Sheet - Standardized'!G$61 -> 0.13948707 | H35: =IF('Balance Sheet - Standardized'!H37="",0,'Balance Sheet - Standardized'!H37)/'Balance Sheet - Standardized'!H$61 -> 0.14438036 | I35: =IF('Balance Sheet - Standardized'!I37="",0,'Balance Sheet - Standardized'!I37)/'Balance Sheet - Standardized'!I$61 -> 0.13293689 | J35: =IF('Balance Sheet - Standardized'!J37="",0,'Balance Sheet - Standardized'!J37)/'Balance Sheet - Standardized'!J$61 -> 0.13368157 | ... L35: =IF('Balance Sheet - Standardized'!L37="",0,'Balance Sheet - Standardized'!L37)/'Balance Sheet - Standardized'!L$61 -> 0.16924466
A36: ='Balance Sheet - Standardized'!A38 -> + Property, Plant & Equip, Net (Standardized) | B36: ='Balance Sheet - Standardized'!B38 -> BS_NET_FIX_ASSET | C36: =IF('Balance Sheet - Standardized'!C38="",0,'Balance Sheet - Standardized'!C38)/'Balance Sheet - Standardized'!C$61 -> 0.15922997 | D36: =IF('Balance Sheet - Standardized'!D38="",0,'Balance Sheet - Standardized'!D38)/'Balance Sheet - Standardized'!D$61 -> 0.14721994 | E36: =IF('Balance Sheet - Standardized'!E38="",0,'Balance Sheet - Standardized'!E38)/'Balance Sheet - Standardized'!E$61 -> 0.11443741 | F36: =IF('Balance Sheet - Standardized'!F38="",0,'Balance Sheet - Standardized'!F38)/'Balance Sheet - Standardized'!F$61 -> 0.13784943 | G36: =IF('Balance Sheet - Standardized'!G38="",0,'Balance Sheet - Standardized'!G38)/'Balance Sheet - Standardized'!G$61 -> 0.18761283 | H36: =IF('Balance Sheet - Standardized'!H38="",0,'Balance Sheet - Standardized'!H38)/'Balance Sheet - Standardized'!H$61 -> 0.17307062 | I36: =IF('Balance Sheet - Standardized'!I38="",0,'Balance Sheet - Standardized'!I38)/'Balance Sheet - Standardized'!I$61 -> 0.15992756 | J36: =IF('Balance Sheet - Standardized'!J38="",0,'Balance Sheet - Standardized'!J38)/'Balance Sheet - Standardized'!J$61 -> 0.15652844 | ... L36: =IF('Balance Sheet - Standardized'!L38="",0,'Balance Sheet - Standardized'!L38)/'Balance Sheet - Standardized'!L$61 -> 0.19076609
A37: ='Balance Sheet - Standardized'!A39 -> + Property, Plant & Equip (Standardized) | B37: ='Balance Sheet - Standardized'!B39 -> BS_GROSS_FIX_ASSET | C37: =IF('Balance Sheet - Standardized'!C39="",0,'Balance Sheet - Standardized'!C39)/'Balance Sheet - Standardized'!C$61 -> 0.37474949 | D37: =IF('Balance Sheet - Standardized'!D39="",0,'Balance Sheet - Standardized'!D39)/'Balance Sheet - Standardized'!D$61 -> 0.37377083 | E37: =IF('Balance Sheet - Standardized'!E39="",0,'Balance Sheet - Standardized'!E39)/'Balance Sheet - Standardized'!E$61 -> 0.34272453 | F37: =IF('Balance Sheet - Standardized'!F39="",0,'Balance Sheet - Standardized'!F39)/'Balance Sheet - Standardized'!F$61 -> 0.37715315 | G37: =IF('Balance Sheet - Standardized'!G39="",0,'Balance Sheet - Standardized'!G39)/'Balance Sheet - Standardized'!G$61 -> 0.41288916 | H37: =IF('Balance Sheet - Standardized'!H39="",0,'Balance Sheet - Standardized'!H39)/'Balance Sheet - Standardized'!H$61 -> 0.38808352 | I37: =IF('Balance Sheet - Standardized'!I39="",0,'Balance Sheet - Standardized'!I39)/'Balance Sheet - Standardized'!I$61 -> 0.36608865 | J37: =IF('Balance Sheet - Standardized'!J39="",0,'Balance Sheet - Standardized'!J39)/'Balance Sheet - Standardized'!J$61 -> 0.36850173 | ... L37: =IF('Balance Sheet - Standardized'!L39="",0,'Balance Sheet - Standardized'!L39)/'Balance Sheet - Standardized'!L$61 -> 0.39621995
A38: ='Balance Sheet - Standardized'!A40 -> - Accumulated Depreciation (Standardized) | B38: ='Balance Sheet - Standardized'!B40 -> BS_ACCUM_DEPR | C38: =IF('Balance Sheet - Standardized'!C40="",0,'Balance Sheet - Standardized'!C40)/'Balance Sheet - Standardized'!C$61 -> 0.21551952 | D38: =IF('Balance Sheet - Standardized'!D40="",0,'Balance Sheet - Standardized'!D40)/'Balance Sheet - Standardized'!D$61 -> 0.22655089 | E38: =IF('Balance Sheet - Standardized'!E40="",0,'Balance Sheet - Standardized'!E40)/'Balance Sheet - Standardized'!E$61 -> 0.22828712 | F38: =IF('Balance Sheet - Standardized'!F40="",0,'Balance Sheet - Standardized'!F40)/'Balance Sheet - Standardized'!F$61 -> 0.23930372 | G38: =IF('Balance Sheet - Standardized'!G40="",0,'Balance Sheet - Standardized'!G40)/'Balance Sheet - Standardized'!G$61 -> 0.22527632 | H38: =IF('Balance Sheet - Standardized'!H40="",0,'Balance Sheet - Standardized'!H40)/'Balance Sheet - Standardized'!H$61 -> 0.21501291 | I38: =IF('Balance Sheet - Standardized'!I40="",0,'Balance Sheet - Standardized'!I40)/'Balance Sheet - Standardized'!I$61 -> 0.20616109 | J38: =IF('Balance Sheet - Standardized'!J40="",0,'Balance Sheet - Standardized'!J40)/'Balance Sheet - Standardized'!J$61 -> 0.21197329 | ... L38: =IF('Balance Sheet - Standardized'!L40="",0,'Balance Sheet - Standardized'!L40)/'Balance Sheet - Standardized'!L$61 -> 0.20545386
A39: ='Balance Sheet - Standardized'!A41 -> Operating Leases | C39: =IF('Balance Sheet - Standardized'!C41="",0,'Balance Sheet - Standardized'!C41)/'Balance Sheet - Standardized'!C$61 -> 0 | D39: =IF('Balance Sheet - Standardized'!D41="",0,'Balance Sheet - Standardized'!D41)/'Balance Sheet - Standardized'!D$61 -> 0 | E39: =IF('Balance Sheet - Standardized'!E41="",0,'Balance Sheet - Standardized'!E41)/'Balance Sheet - Standardized'!E$61 -> 0 | F39: =IF('Balance Sheet - Standardized'!F41="",0,'Balance Sheet - Standardized'!F41)/'Balance Sheet - Standardized'!F$61 -> 0 | G39: =IF('Balance Sheet - Standardized'!G41="",0,'Balance Sheet - Standardized'!G41)/'Balance Sheet - Standardized'!G$61 -> 0.048125765 | H39: =IF('Balance Sheet - Standardized'!H41="",0,'Balance Sheet - Standardized'!H41)/'Balance Sheet - Standardized'!H$61 -> 0.028690255 | I39: =IF('Balance Sheet - Standardized'!I41="",0,'Balance Sheet - Standardized'!I41)/'Balance Sheet - Standardized'!I$61 -> 0.026990669 | J39: =IF('Balance Sheet - Standardized'!J41="",0,'Balance Sheet - Standardized'!J41)/'Balance Sheet - Standardized'!J$61 -> 0.022846874 | ... L39: =IF('Balance Sheet - Standardized'!L41="",0,'Balance Sheet - Standardized'!L41)/'Balance Sheet - Standardized'!L$61 -> 0.021521438
A40: ='Balance Sheet - Standardized'!A42 -> check
A41: ='Balance Sheet - Standardized'!A43 -> + LT Investments & Receivables | B41: ='Balance Sheet - Standardized'!B43 -> BS_LT_INVEST | C41: =IF('Balance Sheet - Standardized'!C43="",0,'Balance Sheet - Standardized'!C43)/'Balance Sheet - Standardized'!C$61 -> 0 | D41: =IF('Balance Sheet - Standardized'!D43="",0,'Balance Sheet - Standardized'!D43)/'Balance Sheet - Standardized'!D$61 -> 0 | E41: =IF('Balance Sheet - Standardized'!E43="",0,'Balance Sheet - Standardized'!E43)/'Balance Sheet - Standardized'!E$61 -> 0 | F41: =IF('Balance Sheet - Standardized'!F43="",0,'Balance Sheet - Standardized'!F43)/'Balance Sheet - Standardized'!F$61 -> 0 | G41: =IF('Balance Sheet - Standardized'!G43="",0,'Balance Sheet - Standardized'!G43)/'Balance Sheet - Standardized'!G$61 -> 0 | H41: =IF('Balance Sheet - Standardized'!H43="",0,'Balance Sheet - Standardized'!H43)/'Balance Sheet - Standardized'!H$61 -> 0 | I41: =IF('Balance Sheet - Standardized'!I43="",0,'Balance Sheet - Standardized'!I43)/'Balance Sheet - Standardized'!I$61 -> 0 | J41: =IF('Balance Sheet - Standardized'!J43="",0,'Balance Sheet - Standardized'!J43)/'Balance Sheet - Standardized'!J$61 -> 0 | ... L41: =IF('Balance Sheet - Standardized'!L43="",0,'Balance Sheet - Standardized'!L43)/'Balance Sheet - Standardized'!L$61 -> 0
...

Sheet Income - GAAP
A1: Ticker | C1: =IF('Balance Sheet - Standardized'!C1="","",'Balance Sheet - Standardized'!C1) -> LNN | D1: ='Balance Sheet - Standardized'!D1 -> US | M1: Errors on check lines | N1: {=SUM(--ISERROR($C$13:$L$13),--ISERROR($C$18:$L$18),--ISERROR($C$20:$L$20),--ISERROR($C$29:$L$29),--ISERROR($C$31:$L$31),--ISERROR($C$36:$L$36),--ISERROR($C$41:$L$41),--ISERROR($C$43:$L$43),--ISERROR($C$49:$L$49),--ISERROR($C$51:$L$51),--ISERROR($C$55:$L$55),--ISERROR($C$59:$L$59),--ISERROR($C$63:$L$63), COUNT($C$13:$L$13) - COUNTIFS($C$13:$L$13,"<.1",$C$13:$L$13,">-.1"), COUNT($C$18:$L$18) - COUNTIFS($C$18:$L$18,"<.1", $C$18:$L$18,">-.1"), COUNT($C$20:$L$20) - COUNTIFS($C$20:$L$20,"<.1", $C$20:$L$20,">-.1"), COUNT($C$29:$L$29) - COUNTIFS($C$29:$L$29,"<.1", $C$29:$L$29,">-.1"), COUNT($C$31:$L$31) - COUNTIFS($C$31:$L$31,"<.1", $C$31:$L$31,">-.1"), COUNT($C$36:$L$36) - COUNTIFS($C$36:$L$36,"<.1", $C$36:$L$36,">-.1"), COUNT($C$41:$L$41) - COUNTIFS($C$41:$L$41,"<.1", $C$41:$L$41,">-.1"), COUNT($C$43:$L$43) - COUNTIFS($C$43:$L$43,"<.1", $C$43:$L$43,">-.1"),COUNT($C$49:$L$49) - COUNTIFS($C$49:$L$49,"<.1", $C$49:$L$49,">-.1"), COUNT($C$51:$L$51) - COUNTIFS($C$51:$L$51,"<.1", $C$51:$L$51,">-.1"), COUNT($C$55:$L$55) - COUNTIFS($C$55:$L$55,"<.1", $C$55:$L$55,">-.1"), COUNT($C$59:$L$59) - COUNTIFS($C$59:$L$59,"<.1", $C$59:$L$59,">-.1"), COUNT($C$63:$L$63) - COUNTIFS($C$63:$L$63,"<.1", $C$63:$L$63,">-.1"))} -> 0
A2: Start Year | C2: ='Balance Sheet - Standardized'!C2 -> FY 2016
A3: End Year | C3: ='Balance Sheet - Standardized'!C3 -> FY 2025
A7: In Millions of USD except Per Share | C7: ='Balance Sheet - Standardized'!C7 -> FY 2016 | D7: ='Balance Sheet - Standardized'!D7 -> FY 2017 | E7: ='Balance Sheet - Standardized'!E7 -> FY 2018 | F7: ='Balance Sheet - Standardized'!F7 -> FY 2019 | G7: ='Balance Sheet - Standardized'!G7 -> FY 2020 | H7: ='Balance Sheet - Standardized'!H7 -> FY 2021 | I7: ='Balance Sheet - Standardized'!I7 -> FY 2022 | J7: ='Balance Sheet - Standardized'!J7 -> FY 2023 | ... L7: ='Balance Sheet - Standardized'!L7 -> FY 2025
A8: 12 Months Ending | C8: ='Balance Sheet - Standardized'!C8 -> 42613 | D8: ='Balance Sheet - Standardized'!D8 -> 42978 | E8: ='Balance Sheet - Standardized'!E8 -> 43343 | F8: ='Balance Sheet - Standardized'!F8 -> 43708 | G8: ='Balance Sheet - Standardized'!G8 -> 44074 | H8: ='Balance Sheet - Standardized'!H8 -> 44439 | I8: ='Balance Sheet - Standardized'!I8 -> 44804 | J8: ='Balance Sheet - Standardized'!J8 -> 45169 | ... L8: ='Balance Sheet - Standardized'!L8 -> 45900
A9: Revenue | B9: SALES_REV_TURN | C9: 516.411 | D9: 517.985 | E9: 547.705 | F9: 444.072 | G9: 474.692 | H9: 567.646 | I9: 770.743 | J9: 674.084 | K9: 607.074 | L9: 676.368 | M9: =IF(OR(K9=0,K9=""),"",L9/K9-1) -> 0.11414424
A10: + Sales & Services Revenue | B10: IS_SALES_AND_SERVICES_REVENUES | C10: 516.411 | D10: 517.985 | E10: 547.705 | F10: 444.072 | G10: 474.692 | H10: 567.646 | I10: 770.743 | J10: 674.084 | K10: 607.074 | L10: 676.368
A11: + Financing Revenue | B11: IS_FINANCING_REVENUE
A12: + Other Revenue | B12: IS_OTHER_REVENUE
A13: check | C13: =ROUND(SUM(C10:C12)-IF(C9="",0,C9),1) -> 0 | D13: =ROUND(SUM(D10:D12)-IF(D9="",0,D9),1) -> 0 | E13: =ROUND(SUM(E10:E12)-IF(E9="",0,E9),1) -> 0 | F13: =ROUND(SUM(F10:F12)-IF(F9="",0,F9),1) -> 0 | G13: =ROUND(SUM(G10:G12)-IF(G9="",0,G9),1) -> 0 | H13: =ROUND(SUM(H10:H12)-IF(H9="",0,H9),1) -> 0 | I13: =ROUND(SUM(I10:I12)-IF(I9="",0,I9),1) -> 0 | J13: =ROUND(SUM(J10:J12)-IF(J9="",0,J9),1) -> 0 | ... L13: =ROUND(SUM(L10:L12)-IF(L9="",0,L9),1) -> 0
A14: - Cost of Revenue | B14: IS_COGS_TO_FE_AND_PP_AND_G | C14: 367.798 | D14: 372.973 | E14: 396.243 | F14: 329.464 | G14: 322.149 | H14: 417.441 | I14: 571.565 | J14: 461.069 | K14: 416.019 | L14: 465.588 | M14: =IF(OR(K14=0,K14=""),"",L14/K14-1) -> 0.11915081
A15: + Cost of Goods & Services | B15: IS_COG_AND_SERVICES_SOLD | C15: 367.798 | D15: 372.973 | E15: 396.243 | F15: 329.464 | G15: 322.149 | H15: 417.441 | I15: 571.565 | J15: 461.069 | K15: 416.019 | L15: 465.588
A16: + Depreciation & Amortization - COGS | B16: IS_DA_COST_OF_REVENUE_GAAP
A17: + Cost of Financing Revenue | B17: IS_COST_OF_FINANCING_REVENUE
A18: check | C18: =ROUND(SUM(C15:C17)-IF(C14="",0,C14),1) -> 0 | D18: =ROUND(SUM(D15:D17)-IF(D14="",0,D14),1) -> 0 | E18: =ROUND(SUM(E15:E17)-IF(E14="",0,E14),1) -> 0 | F18: =ROUND(SUM(F15:F17)-IF(F14="",0,F14),1) -> 0 | G18: =ROUND(SUM(G15:G17)-IF(G14="",0,G14),1) -> 0 | H18: =ROUND(SUM(H15:H17)-IF(H14="",0,H14),1) -> 0 | I18: =ROUND(SUM(I15:I17)-IF(I14="",0,I14),1) -> 0 | J18: =ROUND(SUM(J15:J17)-IF(J14="",0,J14),1) -> 0 | ... L18: =ROUND(SUM(L15:L17)-IF(L14="",0,L14),1) -> 0
A19: Gross Profit | B19: GROSS_PROFIT | C19: 148.613 | D19: 145.012 | E19: 151.462 | F19: 114.608 | G19: 152.543 | H19: 150.205 | I19: 199.178 | J19: 213.015 | K19: 191.055 | L19: 210.78 | M19: =IF(OR(K19=0,K19=""),"",L19/K19-1) -> 0.10324252
A20: check | C20: =ROUND(IF(C9="",0,C9)-IF(C14="",0,C14)-IF(C19="",0,C19),1) -> 0 | D20: =ROUND(IF(D9="",0,D9)-IF(D14="",0,D14)-IF(D19="",0,D19),1) -> 0 | E20: =ROUND(IF(E9="",0,E9)-IF(E14="",0,E14)-IF(E19="",0,E19),1) -> 0 | F20: =ROUND(IF(F9="",0,F9)-IF(F14="",0,F14)-IF(F19="",0,F19),1) -> 0 | G20: =ROUND(IF(G9="",0,G9)-IF(G14="",0,G14)-IF(G19="",0,G19),1) -> 0 | H20: =ROUND(IF(H9="",0,H9)-IF(H14="",0,H14)-IF(H19="",0,H19),1) -> 0 | I20: =ROUND(IF(I9="",0,I9)-IF(I14="",0,I14)-IF(I19="",0,I19),1) -> 0 | J20: =ROUND(IF(J9="",0,J9)-IF(J14="",0,J14)-IF(J19="",0,J19),1) -> 0 | ... L20: =ROUND(IF(L9="",0,L9)-IF(L14="",0,L14)-IF(L19="",0,L19),1) -> 0
A21: + Other Operating Income | B21: IS_OTHER_OPER_INC | C21: 0 | D21: 0 | E21: 0 | F21: 0 | G21: 0 | H21: 0 | I21: 0 | J21: 0 | K21: 0 | L21: 0
A22: - Operating Expenses | B22: IS_OPERATING_EXPN | C22: 114.238 | D22: 104.811 | E22: 112.899 | F22: 108.493 | G22: 98.341 | H22: 96.098 | I22: 104.535 | J22: 110.831 | K22: 114.447 | L22: 122.656 | M22: =IF(OR(K22=0,K22=""),"",L22/K22-1) -> 0.071727525
A23: + Selling, General & Admin | B23: IS_SG&A_EXPENSE | C23: 98.392 | D23: 87.664 | E23: 96.847 | F23: 94.557 | G23: 84.391 | H23: 82.739 | I23: 89.39 | J23: 92.613 | K23: 97.324 | L23: 104.726
A24: + Selling & Marketing | B24: IS_SELLING_EXPENSES | C24: 41.973 | D24: 40.705 | E24: 40.885 | F24: 30.82 | G24: 31.444 | H24: 30.816 | I24: 33.92 | J24: 36.201 | K24: 39.905 | L24: 41.74
A25: + General & Administrative | B25: IS_GENERAL_AND_ADMINISTRATIVE | C25: 56.419 | D25: 46.959 | E25: 55.962 | F25: 63.737 | G25: 52.947 | H25: 51.923 | I25: 55.47 | J25: 56.412 | K25: 57.419 | L25: 62.986
A26: + Research & Development | B26: IS_OPERATING_EXPENSES_R&D | C26: 15.846 | D26: 17.147 | E26: 16.052 | F26: 13.936 | G26: 13.95 | H26: 13.359 | I26: 15.145 | J26: 18.218 | K26: 17.123 | L26: 17.93
A27: + IS Depreciation & Amortization | B27: IS_DEPRECIATION_AND_AMORTIZATION
A28: + Other Operating Expense | B28: OTHER_OPERATING_EXPENSES_RATIO | C28: 0 | D28: 0 | E28: 0 | F28: 0 | G28: 0 | H28: 0 | I28: 0 | J28: 0 | K28: 0 | L28: 0
A29: check | C29: =ROUND(SUM(C23,C26,C27,C28)-IF(C22="",0,C22),1) -> 0 | D29: =ROUND(SUM(D23,D26,D27,D28)-IF(D22="",0,D22),1) -> 0 | E29: =ROUND(SUM(E23,E26,E27,E28)-IF(E22="",0,E22),1) -> 0 | F29: =ROUND(SUM(F23,F26,F27,F28)-IF(F22="",0,F22),1) -> 0 | G29: =ROUND(SUM(G23,G26,G27,G28)-IF(G22="",0,G22),1) -> 0 | H29: =ROUND(SUM(H23,H26,H27,H28)-IF(H22="",0,H22),1) -> 0 | I29: =ROUND(SUM(I23,I26,I27,I28)-IF(I22="",0,I22),1) -> 0 | J29: =ROUND(SUM(J23,J26,J27,J28)-IF(J22="",0,J22),1) -> 0 | ... L29: =ROUND(SUM(L23,L26,L27,L28)-IF(L22="",0,L22),1) -> 0
A30: Operating Income (Loss) | B30: IS_OPER_INC | C30: 34.375 | D30: 40.201 | E30: 38.563 | F30: 6.115 | G30: 54.202 | H30: 54.107 | I30: 94.643 | J30: 102.184 | K30: 76.608 | L30: 88.124 | M30: =IF(OR(K30=0,K30=""),"",L30/K30-1) -> 0.15032373
A31: check | C31: =ROUND(IF(C19="",0,C19)+IF(C21="",0,C21)-IF(C22="",0,C22)-IF(C30="",0,C30),1) -> 0 | D31: =ROUND(IF(D19="",0,D19)+IF(D21="",0,D21)-IF(D22="",0,D22)-IF(D30="",0,D30),1) -> 0 | E31: =ROUND(IF(E19="",0,E19)+IF(E21="",0,E21)-IF(E22="",0,E22)-IF(E30="",0,E30),1) -> 0 | F31: =ROUND(IF(F19="",0,F19)+IF(F21="",0,F21)-IF(F22="",0,F22)-IF(F30="",0,F30),1) -> 0 | G31: =ROUND(IF(G19="",0,G19)+IF(G21="",0,G21)-IF(G22="",0,G22)-IF(G30="",0,G30),1) -> 0 | H31: =ROUND(IF(H19="",0,H19)+IF(H21="",0,H21)-IF(H22="",0,H22)-IF(H30="",0,H30),1) -> 0 | I31: =ROUND(IF(I19="",0,I19)+IF(I21="",0,I21)-IF(I22="",0,I22)-IF(I30="",0,I30),1) -> 0 | J31: =ROUND(IF(J19="",0,J19)+IF(J21="",0,J21)-IF(J22="",0,J22)-IF(J30="",0,J30),1) -> 0 | ... L31: =ROUND(IF(L19="",0,L19)+IF(L21="",0,L21)-IF(L22="",0,L22)-IF(L30="",0,L30),1) -> 0
A32: - Non-Operating (Income) Loss | B32: NONOP_INCOME_LOSS | C32: 5.087 | D32: 4.486 | E32: 4.71 | F32: 4.008 | G32: 5.359 | H32: 3.721 | I32: 6.775 | J32: 1.809 | K32: -2.442 | L32: -6.459
A33: + Interest Expense, Net | B33: IS_NET_INTEREST_EXPENSE | C33: 4.106 | D33: 3.579 | E33: 3.047 | F33: 2.365 | G33: 2.803 | H33: 3.668 | I33: 3.647 | J33: 1.005 | K33: -1.955 | L33: -5.885
A34: + Interest Expense | B34: IS_INT_EXPENSE | C34: 4.751 | D34: 4.757 | E34: 4.687 | F34: 4.767 | G34: 4.759 | H34: 4.751 | I34: 4.269 | J34: 3.788 | K34: 3.234 | L34: 1.833
